<?xml version="1.0"?>
<robot name="simple_diffbot">

  <!-- Base footprint -->
  <link name="base_footprint"/>

  <!-- Base link -->
  <link name="base_link">
    <visual>
      <geometry>
        <cylinder radius="0.15" length="0.05"/>
      </geometry>
    </visual>
  </link>

  <joint name="base_footprint_to_base_link" type="fixed">
    <parent link="base_footprint"/>
    <child link="base_link"/>
    <origin xyz="0 0 0.05" rpy="0 0 0"/>
  </joint>

  <!-- Left wheel -->
  <link name="left_wheel">
    <visual>
      <geometry>
        <cylinder radius="0.05" length="0.03"/>
      </geometry>
      <origin xyz="0 0 0" rpy="1.57 0 0"/>
    </visual>
  </link>

  <joint name="left_wheel_joint" type="continuous">
    <parent link="base_link"/>
    <child link="left_wheel"/>
    <origin xyz="0 0.12 -0.025" rpy="0 0 0"/>
    <axis xyz="0 1 0"/>
  </joint>

  <!-- Right wheel -->
  <link name="right_wheel">
    <visual>
      <geometry>
        <cylinder radius="0.05" length="0.03"/>
      </geometry>
      <origin xyz="0 0 0" rpy="1.57 0 0"/>
    </visual>
  </link>

  <joint name="right_wheel_joint" type="continuous">
    <parent link="base_link"/>
    <child link="right_wheel"/>
    <origin xyz="0 -0.12 -0.025" rpy="0 0 0"/>
    <axis xyz="0 1 0"/>
  </joint>

  <!-- Caster -->
  <link name="caster">
    <visual>
      <geometry>
        <sphere radius="0.025"/>
      </geometry>
    </visual>
  </link>

  <joint name="caster_joint" type="fixed">
    <parent link="base_link"/>
    <child link="caster"/>
    <origin xyz="-0.12 0 -0.05" rpy="0 0 0"/>
  </joint>

  <!-- Lidar -->
  <link name="lidar">
    <visual>
      <geometry>
        <cylinder radius="0.03" length="0.04"/>
      </geometry>
    </visual>
  </link>

  <joint name="lidar_joint" type="fixed">
    <parent link="base_link"/>
    <child link="lidar"/>
    <origin xyz="0 0 0.045" rpy="0 0 0"/>
  </joint>

</robot>
