<?xml version="1.0"?>
<robot name="trivial">
  <link name="base_footprint">
    <visual>
      <geometry>
        <sphere radius="0.005" />
      </geometry>
    </visual>
    <collision>
      <geometry>
        <sphere radius="0.005" />
      </geometry>
    </collision>
  </link>
  <link name="base_link">
    <visual>
      <geometry>
        <cylinder radius="0.14" length="0.003" />
      </geometry>
    </visual>
    <collision>
      <geometry>
        <cylinder radius="0.14" length="0.003" />
      </geometry>
    </collision>
  </link>
  <link name="left_wheel">
    <visual>
      <origin rpy="1.57 0 0" />
      <geometry>
        <cylinder radius="0.03125" length="0.024" />
      </geometry>
    </visual>
    <collision>
      <origin rpy="1.57 0 0" />
      <geometry>
        <cylinder radius="0.03125" length="0.024" />
      </geometry>
    </collision>
  </link>
  <link name="right_wheel">
    <visual>
      <origin rpy="1.57 0 0" />
      <geometry>
        <cylinder radius="0.03125" length="0.024" />
      </geometry>
    </visual>
    <collision>
      <origin rpy="1.57 0 0" />
      <geometry>
        <cylinder radius="0.03125" length="0.024" />
      </geometry>
    </collision>
  </link>
  <joint name="base_footprint_to_base_link" type="fixed">
    <parent link="base_footprint" />
    <child link="base_link" />
    <origin xyz="0.085 0 0.065" />
  </joint>
  <joint name="base_link_to_left_wheel" type="continuous">
    <parent link="base_link" />
    <child link="left_wheel" />
    <origin xyz="0 0.1075 -0.04" />
    <axis xyz="0 1 0" />
  </joint>
  <joint name="base_link_to_right_wheel" type="continuous">
    <parent link="base_link" />
    <child link="right_wheel" />
    <origin xyz="0 -0.1075 -0.04" />
    <axis xyz="0 1 0" />
  </joint>
</robot>
