<?xml version="1.0"?>
<robot name="octagon_bot">
  <!-- Materials -->
  <material name="clear">
    <color rgba="0.9 0.9 0.9 0.3"/>
  </material>
  <material name="black">
    <color rgba="0 0 0 1"/>
  </material>

  <!-- Links -->
  <link name="base_footprint"/>

  <link name="base_link">
    <visual>
      <geometry>
        <cylinder radius="0.15" length="0.003"/>
      </geometry>
      <material name="clear"/>
    </visual>
    <collision>
      <geometry>
        <cylinder radius="0.15" length="0.003"/>
      </geometry>
    </collision>
  </link>

  <link name="left_wheel">
    <visual>
      <origin rpy="1.5708 0 0"/>
      <geometry>
        <cylinder radius="0.035" length="0.02"/>
      </geometry>
      <material name="black"/>
    </visual>
    <collision>
      <origin rpy="1.5708 0 0"/>
      <geometry>
        <cylinder radius="0.035" length="0.02"/>
      </geometry>
    </collision>
  </link>

  <link name="right_wheel">
    <visual>
      <origin rpy="1.5708 0 0"/>
      <geometry>
        <cylinder radius="0.035" length="0.02"/>
      </geometry>
      <material name="black"/>
    </visual>
    <collision>
      <origin rpy="1.5708 0 0"/>
      <geometry>
        <cylinder radius="0.035" length="0.02"/>
      </geometry>
    </collision>
  </link>

  <!-- Joints -->
  <joint name="base_footprint_to_base_link" type="fixed">
    <parent link="base_footprint"/>
    <child link="base_link"/>
    <origin xyz="0 0 0.05"/>
  </joint>

  <joint name="base_link_to_left_wheel" type="continuous">
    <parent link="base_link"/>
    <child link="left_wheel"/>
    <origin xyz="0 0.10 -0.015"/>
    <axis xyz="0 1 0"/>
  </joint>

  <joint name="base_link_to_right_wheel" type="continuous">
    <parent link="base_link"/>
    <child link="right_wheel"/>
    <origin xyz="0 -0.10 -0.015"/>
    <axis xyz="0 1 0"/>
  </joint>
</robot>
