<?xml version="1.0"?>
<robot name="dome2">
  <material name="gray">
    <color rgba="0.5 0.5 0.5 1.0" />
  </material>
  <material name="black">
    <color rgba="0 0 0 1" />
  </material>
  <material name="red">
    <color rgba="1 0 0 1" />
  </material>
  <material name="blue">
    <color rgba="0.3 0.3 0.8 1" />
  </material>
  <material name="green">
    <color rgba="0 0.8 0 1" />
  </material>
  <material name="yellow">
    <color rgba="1 1 0 1" />
  </material>
  <material name="white">
    <color rgba="1 1 1 1" />
  </material>
  <material name="dark_red">
    <color rgba="0.5 0 0 1" />
  </material>
  <material name="dark_green">
    <color rgba="0 0.4 0 1" />
  </material>
  <link name="base_footprint" />
  <link name="base_link">
    <visual>
      <geometry>
        <cylinder radius="0.15" length="0.003" />
      </geometry>
      <material name="gray" />
    </visual>
    <collision>
      <geometry>
        <cylinder radius="0.15" length="0.003" />
      </geometry>
    </collision>
  </link>
  <link name="left_wheel">
    <visual>
      <origin rpy="1.5707963267948966 0 0" />
      <geometry>
        <cylinder radius="0.03" length="0.0175" />
      </geometry>
      <material name="green" />
    </visual>
    <collision>
      <origin rpy="1.5707963267948966 0 0" />
      <geometry>
        <cylinder radius="0.03" length="0.0175" />
      </geometry>
    </collision>
  </link>
  <link name="right_wheel">
    <visual>
      <origin rpy="1.5707963267948966 0 0" />
      <geometry>
        <cylinder radius="0.03" length="0.0175" />
      </geometry>
      <material name="red" />
    </visual>
    <collision>
      <origin rpy="1.5707963267948966 0 0" />
      <geometry>
        <cylinder radius="0.03" length="0.0175" />
      </geometry>
    </collision>
  </link>
  <link name="caster">
    <visual>
      <geometry>
        <sphere radius="0.015" />
      </geometry>
      <material name="gray" />
    </visual>
    <collision>
      <geometry>
        <sphere radius="0.015" />
      </geometry>
    </collision>
  </link>
  <link name="laser_post_link">
    <visual>
      <geometry>
        <box size="0.01 0.01 0.09" />
      </geometry>
      <material name="blue" />
    </visual>
    <collision>
      <geometry>
        <box size="0.01 0.01 0.09" />
      </geometry>
    </collision>
  </link>
  <link name="laser">
    <visual>
      <geometry>
        <cylinder radius="0.03" length="0.05" />
      </geometry>
      <material name="dark_green" />
    </visual>
    <collision>
      <geometry>
        <cylinder radius="0.03" length="0.05" />
      </geometry>
    </collision>
  </link>
  <link name="laser_forward_link">
    <visual>
      <geometry>
        <box size="0.04 0.002 0.002" />
      </geometry>
      <material name="red" />
    </visual>
    <collision>
      <geometry>
        <box size="0.04 0.002 0.002" />
      </geometry>
    </collision>
  </link>
  <link name="laser_left_link">
    <visual>
      <geometry>
        <box size="0.002 0.04 0.002" />
      </geometry>
      <material name="green" />
    </visual>
    <collision>
      <geometry>
        <box size="0.002 0.04 0.002" />
      </geometry>
    </collision>
  </link>
  <link name="laser_up_link">
    <visual>
      <geometry>
        <box size="0.002 0.002 0.04" />
      </geometry>
      <material name="blue" />
    </visual>
    <collision>
      <geometry>
        <box size="0.002 0.002 0.04" />
      </geometry>
    </collision>
  </link>
  <link name="imu_link">
    <visual>
      <geometry>
        <box size="0.03 0.02 0.01" />
      </geometry>
      <material name="dark_red" />
    </visual>
    <collision>
      <geometry>
        <box size="0.03 0.02 0.01" />
      </geometry>
    </collision>
  </link>
  <link name="imu_forward_link">
    <visual>
      <geometry>
        <box size="0.03 0.002 0.002" />
      </geometry>
      <material name="red" />
    </visual>
    <collision>
      <geometry>
        <box size="0.03 0.002 0.002" />
      </geometry>
    </collision>
  </link>
  <link name="imu_left_link">
    <visual>
      <geometry>
        <box size="0.002 0.03 0.002" />
      </geometry>
      <material name="green" />
    </visual>
    <collision>
      <geometry>
        <box size="0.002 0.03 0.002" />
      </geometry>
    </collision>
  </link>
  <link name="imu_up_link">
    <visual>
      <geometry>
        <box size="0.002 0.002 0.03" />
      </geometry>
      <material name="blue" />
    </visual>
    <collision>
      <geometry>
        <box size="0.002 0.002 0.03" />
      </geometry>
    </collision>
  </link>
  <link name="origin_marker_link">
    <visual>
      <geometry>
        <sphere radius="0.001" />
      </geometry>
      <material name="yellow" />
    </visual>
    <collision>
      <geometry>
        <sphere radius="0.001" />
      </geometry>
    </collision>
  </link>
  <joint name="base_footprint_to_base_link" type="fixed">
    <parent link="base_footprint" />
    <child link="base_link" />
    <origin xyz="0 0 0.05" />
  </joint>
  <joint name="base_link_to_left_wheel" type="continuous">
    <parent link="base_link" />
    <child link="left_wheel" />
    <origin xyz="0.1 0.125 -0.03" />
    <axis xyz="0 1 0" />
  </joint>
  <joint name="base_link_to_right_wheel" type="continuous">
    <parent link="base_link" />
    <child link="right_wheel" />
    <origin xyz="0.1 -0.125 -0.03" />
    <axis xyz="0 1 0" />
  </joint>
  <joint name="base_link_to_caster" type="fixed">
    <parent link="base_link" />
    <child link="caster" />
    <origin xyz="-0.12 0 -0.05" />
  </joint>
  <joint name="base_link_to_imu_link" type="fixed">
    <parent link="base_link" />
    <child link="imu_link" />
    <origin xyz="0.03 0 0.053" rpy="1.5707963267948966 0 3.141592653589793" />
  </joint>
  <joint name="imu_link_to_imu_forward_link" type="fixed">
    <parent link="imu_link" />
    <child link="imu_forward_link" />
    <origin xyz="0.015 0 0" />
  </joint>
  <joint name="imu_link_to_imu_left_link" type="fixed">
    <parent link="imu_link" />
    <child link="imu_left_link" />
    <origin xyz="0 0.01 0" />
  </joint>
  <joint name="imu_link_to_imu_up_link" type="fixed">
    <parent link="imu_link" />
    <child link="imu_up_link" />
    <origin xyz="0 0 0.015" />
  </joint>
  <joint name="base_link_to_origin_marker_link" type="fixed">
    <parent link="base_link" />
    <child link="origin_marker_link" />
    <origin xyz="0 0 0" />
  </joint>
  <joint name="base_link_to_laser_post_link" type="fixed">
    <parent link="base_link" />
    <child link="laser_post_link" />
    <origin xyz="0 0 0.05" />
  </joint>
  <joint name="base_link_to_laser" type="fixed">
    <parent link="base_link" />
    <child link="laser" />
    <origin xyz="0 0 0.1" rpy="0 0 -1.5707963267948966" />
  </joint>
  <joint name="laser_to_laser_forward_link" type="fixed">
    <parent link="laser" />
    <child link="laser_forward_link" />
    <origin xyz="0.02 0 0" />
  </joint>
  <joint name="laser_to_laser_left_link" type="fixed">
    <parent link="laser" />
    <child link="laser_left_link" />
    <origin xyz="0 0.02 0" />
  </joint>
  <joint name="laser_to_laser_up_link" type="fixed">
    <parent link="laser" />
    <child link="laser_up_link" />
    <origin xyz="0 0 0.03" />
  </joint>
</robot>
