<?xml version="1.0"?>
<robot name="mesh_demo">
  <material name="blue">
    <color rgba="0 0 0.8 1" />
  </material>
  <material name="gray">
    <color rgba="0.5 0.5 0.5 1" />
  </material>
  <link name="base_footprint" />
  <link name="base_link">
    <visual>
      <geometry>
        <mesh filename="cube.obj" />
      </geometry>
    </visual>
    <collision>
      <geometry>
        <mesh filename="cube.obj" />
      </geometry>
    </collision>
  </link>
  <link name="sensor_link">
    <visual>
      <origin rpy="0 0 0.7853981633974483" />
      <geometry>
        <mesh filename="cube.obj" scale="0.5 0.5 0.5" />
      </geometry>
    </visual>
    <collision>
      <origin rpy="0 0 0.7853981633974483" />
      <geometry>
        <mesh filename="cube.obj" scale="0.5 0.5 0.5" />
      </geometry>
    </collision>
  </link>
  <link name="arm_link">
    <visual>
      <geometry>
        <cylinder radius="0.02" length="0.3" />
      </geometry>
      <material name="gray" />
    </visual>
    <collision>
      <geometry>
        <cylinder radius="0.02" length="0.3" />
      </geometry>
    </collision>
  </link>
  <joint name="base_footprint_to_base_link" type="fixed">
    <parent link="base_footprint" />
    <child link="base_link" />
    <origin xyz="0 0 0.05" />
  </joint>
  <joint name="base_link_to_sensor_link" type="fixed">
    <parent link="base_link" />
    <child link="sensor_link" />
    <origin xyz="0.2 0 0.1" />
  </joint>
  <joint name="base_link_to_arm_link" type="revolute">
    <parent link="base_link" />
    <child link="arm_link" />
    <origin xyz="0 0 0.15" />
    <axis xyz="0 0 1" />
  </joint>
</robot>
